<?xml version='1.0'?>

<robot name="myrobot" xmlns:xacro="http://www.ros.org/wiki/xacro">
    <xacro:include filename="$(find mybot_description)/urdf/mybot.gazebo" />

    <link name="chassis">
      <inertial>
        <mass value="2.0"/>
        <origin rpy="0 0 0" xyz="0 0 0"/>
        <inertia ixx="0.08025" ixy="0" ixz="0"
                 iyy="0.08025" iyz="0"
                 izz="0.1445"
        />
      </inertial>

      <collision>
        <origin rpy="1.57079632679 0.0 1.57079632679" xyz="0.0 0.0 0.086"/>
        <geometry>
          <mesh filename="file://$(find mybot_description)/meshes/*.dae file" scale="0.002 0.002 0.002"/>
        </geometry>
      </collision>

      <visual>
        <origin rpy="1.57079632679 0.0 1.57079632679" xyz="0.0 0.0 0.086"/>
        <geometry>
          <mesh filename="file://$(find mybot_description)/meshes/*.dae file" scale="0.002 0.002 0.002"/>
        </geometry>
      </visual>
    </link>


    <link name="left_wheel">
      <inertial>
        <mass value="0.3"/>
        <origin rpy="0 0 0" xyz="0 0 0"/>
        <inertia ixx="0.000129167" ixy="0" ixz="0"
                 iyy="0.000129167" iyz="0"
                 izz="0.0000225"
        />
      </inertial>

      <collision>
        <origin rpy="0 0 0" xyz="0 0 0"/>
        <geometry>
          <mesh filename="file://$(find mybot_description)/meshes/*.dae file" scale="0.002 0.002 0.002"/>
        </geometry>
      </collision>

      <visual>
        <origin rpy="0 0 0" xyz="0 0 0"/>
          <geometry>
            <mesh filename="file://$(find mybot_description)/meshes/*.dae file" scale="0.002 0.002 0.002"/>
          </geometry>
      </visual>
    </link>


    <joint name='left_wheel_hinge' type='revolute'>
      <origin rpy="0.0 0.0 1.57079632679" xyz="0.06 0.1025 0.06"/>
      <child  link="left_wheel"/>
      <parent link="chassis"/>
      <axis rpy="0 0 0" xyz="1 0 0"/>
      <limit lower="-1e+16" upper="1e+16" effort="100" velocity="100"/>
    </joint>


    <link name="right_wheel">
      <inertial>
        <mass value="0.3"/>
        <origin rpy="0 0 0" xyz="0 0 0"/>
        <inertia ixx="0.000129167" ixy="0" ixz="0"
                 iyy="0.000129167" iyz="0"
                 izz="0.0000225"
        />
      </inertial>

      <collision>
        <origin rpy="0 0 0" xyz="0 0 0"/>
        <geometry>
          <mesh filename="file://$(find mybot_description)/meshes/*.dae file" scale="0.002 0.002 0.002"/>
        </geometry>
      </collision>

      <visual>
        <origin rpy="0 0 0" xyz="0 0 0"/>
        <geometry>
          <mesh filename="file://$(find mybot_description)/meshes/*.dae file" scale="0.002 0.002 0.002"/>
        </geometry>
      </visual>
    </link>


    <joint name='right_wheel_hinge' type='revolute'>
      <origin rpy="0.0 0.0 1.57079632679 " xyz="0.06 -0.119 0.06"/>
      <child  link="right_wheel"/>
      <parent link="chassis"/>
      <axis rpy="0 0 0" xyz="1 0 0"/>
      <limit lower="-1e+16" upper="1e+16" effort="100" velocity="100"/>
    </joint>

</robot>
